Workbook

Sheet Question
B1: 0 | C1: 0
A2: Revenue | C2: 180000
A3: Bank Balance | B3: 7500
A4: Buildings at cost | B4: 45000
A5: Buildings depreciation at 1st Jan 2025 | C5: 9000
A6: Equipment at cost | B6: 37500
A7: Equipment depreciation at 1st Jan 2025 | C7: 7500
A8: Land at cost | B8: 150000
A9: Purchases | B9: 49500
A10: Goodwill | B10: 7500
A11: Heating & Lighting | B11: 1500
A12: Administrative Expenses | B12: 2250
A13: Trade Receivables | B13: 6750
A14: Trade Payables | C14: 6000
A15: Factory Wages | B15: 2250
A16: Administrative Salaries | B16: 3750
A17: Distribution Salaries | B17: 7500
A18: 10% Loan | C18: 12000
A19: Provision for doubtful debts at 1st Jan 2025 | C19: 300
A20: Directors Remuneration | B20: 6750
A21: Retained Profits | C21: 25200
A22: £1 Ordinary shares | C22: 75000
A23: Inventory at 1st Jan 2025 | B23: 2250
A24: Share Premium | C24: 15000
B25: 330000 | C25: 330000
A27: 1. Inventory | B27: -1200
A28: 2. Admin salaries | B28: 70
A29: 3. CEO | B29: 120
A30: Sales director | B30: 80
A31: 4. Provision for doubtful debt | B31: 600
A32: 5. Equipment Depreciation | B32: 0.2
A33: Cost of sales | B33: 0.5
A34: Distribution exp | B34: 0.5
A35: 6. Building Depreciation | B35: 0.1
A36: Cost of sales | B36: 0.2
A37: Admin exp | B37: 0.4
A38: Distribution exp | B38: 0.4
A39: 7. Tax exp | B39: 1000
A40: 8. Land revaluation | B40: 180000 | C40: =B40-B8 -> 30000

Sheet Q1 SOPL
A1: Robert Plc
A2: Statement of Profit & Loss & Other Comprehensive Income year ended 31st December 2025
A3: Revenue | B3: =Question!$C$2 -> 180000
A4: Cost of sales (W1) | B4: 58950
A5: Gross Profit | B5: =B3-B4 -> 121050
A6: Distribution Costs (W1) | B6: 13130
A7: Administrative Costs (W1) | B7: 15040
A9: Profit From Operations | B9: =B5-B6-B7 -> 92880
A10: Finance Costs | B10: 2400
A12: Profit Before tax | B12: =B9-B10 -> 90480
A13: Tax | B13: 1000
A15: Profit for the year | B15: =B12-B13 -> 89480
A17: *note where a company has gains/losses that are being taken directly to
A18: reserves these need to be reported in 'Other comprehensive income'
A20: Other comprehensive income
A22: Revaluation | B22: 30000 | C22: (180,000-150,000)
A24: Total comprehensive income | B24: =B15+B22 -> 119480

Sheet Q1 SOFP
A1: Robert Plc
A2: Statement of Financial Position as at 31st Dec 2025
A3: Assets | E3: 0
A4: Non-Current Assets
A5: Goodwill - intangible assets | E5: =Question!$B$10 -> 7500
A6: Property, Plant & equipment (W3) | E6: ='Q1 Workings'!$E$45 -> 234000
A7: Total Non-current asset | E7: =SUM(E5:E6) -> 241500
A8: Current Assets
A9: Inventories (closing) | E9: 1200
A10: Trade & other recievables | E10: 6150 | F10: (6750-600)
A11: Cash & Cash equivalents | E11: =Question!$B$3 -> 7500
E12: =SUM(E9:E11) -> 14850
A14: Total Assets | E14: =E7+E12 -> 256350
A16: Equity & Liabilities
A17: Equity
A18: Equity Share capital | E18: =Question!$C$22 -> 75000
A19: Share Premium | E19: =Question!$C$24 -> 15000
A20: Revaluation Reserve | E20: =Question!$C$40 -> 30000
A21: Retained Earnings (W4) | E21: ='Q1 Workings'!$B$53 -> 114680
E22: =SUM(E18:E21) -> 234680
A23: Non-current Liabilities
A24: 20% Loan | E24: =Question!$C$18 -> 12000
E25: =SUM(E24:E24) -> 12000
A27: Current Liabilites
A28: Trade & other payables (W5) | E28: ='Q1 Workings'!$B$59 -> 8670
A29: Current tax Payable | E29: 1000
E30: =SUM(E28:E29) -> 9670
A32: Total Liabilities | E32: =E25+E30 -> 21670
A34: Total Equity & Liabilities | E34: =E22+E32 -> 256350 | F34: =E14-E34 -> 0

Sheet Q1 Workings
A2: Working 1 - Allocation of expenses
B4: Cost of sales | C4: Distribution | D4: Administrative
A5: Opening inventory | B5: =Question!$B$23 -> 2250
A6: Purchases | B6: =Question!$B$9 -> 49500
A7: Closing Inventory | B7: =Question!$B$27 -> -1200
A8: Distribution salaries | C8: =Question!$B$17 -> 7500
A9: Directors remuneration | D9: =Question!$B$20 -> 6750
A10: Directors bonus accrual | C10: =Question!$B$30 -> 80 | D10: =Question!$B$29 -> 120
A11: Heating & lighting | B11: =Question!$B$11 -> 1500
A12: Admin Salaries | D12: =Question!$B$16 -> 3750
A13: factory wages | B13: =Question!$B$15 -> 2250
A14: Admin Expenses | D14: =Question!$B$12 -> 2250
A15: Depreciation - Buildings W2 | B15: =B27 -> 900 | C15: =C27 -> 1800 | D15: =D27 -> 1800
A16: Depreciation - Equipment W2 | B16: =B33 -> 3750 | C16: =C33 -> 3750 | D16: =D33 -> 0
A17: Admin salaries accrued | D17: =Question!$B$28 -> 70
A18: Provision for doubtful debt | D18: 300
B19: =SUM(B5:B18) -> 58950 | C19: =SUM(C5:C18) -> 13130 | D19: =SUM(D5:D18) -> 15040
A21: Working 2 - Depreciation
A23: Buildings
A24: 45000 * 10% | B24: 4500
B25: Cost of sales | C25: Distribution | D25: Administrative
B26: =Question!$B$36 -> 0.2 | C26: 0.4 | D26: 0.4
B27: =B24*B26 -> 900 | C27: =B24*C26 -> 1800 | D27: =$B$24*D26 -> 1800
A29: Equipment
A30: 37500*20% | B30: 7500
B31: Cost of sales | C31: Distribution | D31: Administrative
B32: 0.5 | C32: 0.5 | D32: 0
B33: =$B$30*B32 -> 3750 | C33: =$B$30*C32 -> 3750 | D33: =$B$30*D32 -> 0
A35: Working 3 - Property, Plant & Equipment
B37: Land | C37: Building | D37: Equipment | E37: Total
A39: Cost @ 1 jan 2024 | B39: =Question!$B$8 -> 150000 | C39: =Question!$B$4 -> 45000 | D39: =Question!$B$6 -> 37500 | E39: =SUM(B39:D39) -> 232500
A40: Revaluation | B40: =Question!$C$40 -> 30000 | C40: 0 | E40: =SUM(B40:D40) -> 30000
B41: =SUM(B39:B40) -> 180000 | C41: =SUM(C39:C40) -> 45000 | D41: =SUM(D39:D40) -> 37500 | E41: =SUM(E39:E40) -> 262500
A42: Less:Acc.Dep | B42: 0 | C42: =Question!$C$5 -> 9000 | D42: =Question!$C$7 -> 7500 | E42: =SUM(B42:D42) -> 16500
A43: Current year Dep | C43: =B24 -> 4500 | D43: =B30 -> 7500 | E43: =SUM(C43:D43) -> 12000
A45: NBV @ 31 Dec 2024 | B45: =B41-B42-B43 -> 180000 | C45: =C41-C42-C43 -> 31500 | D45: =D41-D42-D43 -> 22500 | E45: =E41-E42-E43 -> 234000
A48: Working 4 - Retained Earnings
A50: Retained earnings b/fwd | B50: =Question!$C$21 -> 25200
A51: Profit for period | B51: ='Q1 SOPL'!$B$15 -> 89480
A52: Dividend paid | B52: 0
...

Sheet Q2 cashflow
A1: Billls PLC
A2: Statement of Cashflow
A3: For the year ended as of 31st March 2025
D4: 000,
A5: Cashflow from operating activities
A6: Profit from operation | D6: 2213
A7: Add: Depreciation | D7: 2952
A8: Less: Profit on disposal of PPE | D8: -217
B9: 2025 | C9: 2024
A10: Less: Inventories | B10: 2701 | C10: 2019 | D10: =C10-B10 -> -682
A11: Less: Trade and other receivable | B11: 2456 | C11: 1009 | D11: =C11-B11 -> -1447
A12: Add: Trade and other payables | B12: 1140 | C12: 1113 | D12: =B12-C12 -> 27
A13: Less: Interest paid | D13: -210
A14: Less; Tax paid | D14: -466
A15: Net cashflow from operating activities | D15: =SUM(D6:D14) -> 2170
A16: Cashflow from investing activities
A17: Disposal of PPE (W1) | D17: 1254
A18: Acquisition of PPE (W2) | D18: -9900
A19: Net cashflow from investing activites | D19: =D17+D18 -> -8646
A20: Cashflow from financing activities
B21: 2025 | C21: 2024
A22: Share capital | B22: 6000 | C22: 4000 | D22: 2000
A23: Share premium | B23: 4000 | C23: 1000 | D23: 3000
A24: Bank loan | B24: 3000 | C24: 2000 | D24: 1000
A25: Dividend paid | D25: -600
A26: Net cashflow from financing activities | D26: =SUM(D22:D25) -> 5400
A27: Net cash increase/decrease | D27: =D15+D19+D26 -> -1076
A28: Cash and Cash equivalent at the beginging of the year | D28: 392
A29: Cash and Cash equivalent at the end of the year | D29: =D27+D28 -> -684
A30: W-1 Sales of PPE
A31: Cost of PPE | B31: 2048
A32: Less; Acc. Dep | B32: 1011
A33: Book value | B33: =B31-B32 -> 1037
A34: Add: Profit | B34: 217
A35: Sales price | B35: =B33+B34 -> 1254
A37: W-2 Acquisition of PPE | E37: Dr | G37: PPE | J37: Cr
A38: Opening balance | B38: 16797
A39: Less: Depreciation | B39: -2952 | E39: Opening balance | G39: 16797 | H39: Depreciation | J39: 2952
A40: Less: Book value of PPE (W1) | B40: -1037 | H40: Book value | J40: 1037
A41: Less: Closing balance | B41: -22708 | E41: Purchase of New PPE | G41: =G44-G39 -> 9900
...

Sheet Q3 Capital Project
A1: a. Net present value
A2: Project A | B2: Year-0 | C2: Year-1 | D2: Year-2 | E2: Year-3 | F2: Year-4 | G2: Year-5
A3: Investment required | B3: 500000
A4: Working capital | B4: 80000 | G4: 80000
A5: Cash inflow | C5: 300000 | D5: 300000 | E5: 300000 | F5: 300000 | G5: 300000
A6: Cash savings | C6: 65000 | D6: 65000 | E6: 65000 | F6: 65000 | G6: 65000
A7: Running cost | C7: -91000 | D7: -91000 | E7: -91000 | F7: -91000 | G7: -91000
A8: Disposal value | G8: 15000
A9: Total cashflow | C9: =SUM(C5:C8) -> 274000 | D9: =SUM(D5:D8) -> 274000 | E9: =SUM(E5:E8) -> 274000 | F9: =SUM(F5:F8) -> 274000 | G9: =SUM(G4:G8) -> 369000
A10: Interest factor (10%) | C10: 0.9091 | D10: 0.8264 | E10: 0.7513 | F10: 0.683 | G10: 0.6209
A11: Present value | B11: -580000 | C11: =C9*C10 -> 249093.4 | D11: =D9*D10 -> 226433.6 | E11: =E9*E10 -> 205856.2 | F11: =F9*F10 -> 187142 | G11: =G9*G10 -> 229112.1
A12: Total PV | B12: =SUM(C11:G11) -> 1097637.3
A13: NPV | B13: =B12+B11 -> 517637.3
A15: Project B | B15: Year-0 | C15: Year-1 | D15: Year-2 | E15: Year-3
A16: Investment required | B16: 290000
A17: Working capital | B17: 60500 | E17: 60500
A18: Cash inflow | C18: 190000 | D18: 190000 | E18: 190000
A19: Cash savings | C19: 62000 | D19: 62000 | E19: 62000
A20: Running cost | C20: -94000 | D20: -94000 | E20: -94000
A21: Total cashflow | C21: =SUM(C17:C20) -> 158000 | D21: =SUM(D17:D20) -> 158000 | E21: =SUM(E17:E20) -> 218500
A22: Interest factor (10%) | C22: 0.9091 | D22: 0.8264 | E22: 0.7513
A23: Present value | B23: -350500 | C23: =C21*C22 -> 143637.8 | D23: =D21*D22 -> 130571.2 | E23: =E21*E22 -> 164159.05
A24: Total PV | B24: =SUM(C23:E23) -> 438368.05
A25: NPV | B25: =B24+B23 -> 87868.05
A27: Project C | B27: Year-0 | C27: Year-1 | D27: Year-2 | E27: Year-3 | F27: Year-4 | G27: Year-5
A28: Investment required | B28: 330000
A29: Working capital | B29: 20000 | G29: 20000
A30: Cash inflow | C30: 120000 | D30: 120000 | E30: 120000 | F30: 120000 | G30: 120000
A31: Cash savings | C31: 25000 | D31: 25000 | E31: 25000 | F31: 25000 | G31: 25000
A32: Running cost | C32: -35000 | D32: -35000 | E32: -35000 | F32: -35000 | G32: -35000
A33: Total cashflow | C33: =SUM(C29:C32) -> 110000 | D33: =SUM(D29:D32) -> 110000 | E33: =SUM(E29:E32) -> 110000 | F33: =SUM(F29:F32) -> 110000 | G33: =SUM(G29:G32) -> 130000
A34: Interest factor (10%) | C34: 0.9091 | D34: 0.8264 | E34: 0.7513 | F34: 0.683 | G34: 0.6209
A35: Present value | B35: -350000 | C35: =C33*C34 -> 100001 | D35: =D33*D34 -> 90904 | E35: =E33*E34 -> 82643 | F35: =F33*F34 -> 75130 | G35: =G33*G34 -> 80717
A36: Total PV | B36: =SUM(C35:G35) -> 429395
A37: NPV | B37: =B36+B35 -> 79395
A39: B. Payback period
B40: Year-0 | C40: Year-1 | D40: Year-2
A41: Project A | B41: 580000 | C41: 274000 | D41: 274000
B42: 32,000/274,000 | C42: 0.117
A43: PBP= | B43: 2.117 Years
...

Sheet Q4.Ratio
B1: Tay Ltd | C1: Dundee Ltd
A2: a. Return on capital employed
A3: (PBIT/Capital+RE+long-term loan)*100 | B3: (1,120/2,000+2,820+500)*100 | C3: (990/2,000+1,030+3,500)*100
B4: 0.2105 | C4: 0.1516
A5: b. Return on equity
A6: (Profit after tax/ Total equity )*100 | B6: (750/4,820)*100 | C6: (430/3,030)*100
B7: 0.1556 | C7: 0.1419
A8: c. Gross profit margin
A9: (Gross profit/ sales)*100 | B9: (1,880/5,720)*100 | C9: (2,070/6,310)*100
B10: 0.3287 | C10: 0.3281
A11: d. Net profit margin
A12: (Net profit/sales)*100 | B12: (1,070/5,720)*100 | C12: (640/6,310)*100
B13: 0.1871 | C13: 0.1014
A14: e. Current ratio
A15: Current asset/ current liability | B15: 1,520/770 | C15: 1980/1,780
B16: 1.97:1 | C16: 1.11:1
A17: f. Quick ratio
A18: Current asset-Inventory/ current liability | B18: 1,520-510/770 | C18: 1,980-890/1,780
B19: 1.31:1 | C19: 0.61:1
A20: g. Inventory holding periods
A21: (Inventory/ cost of sales)*365 | B21: (510/3,840)*365 | C21: (890/2,240)*365
B22: 49 days | C22: 77 days
A23: h. Trade receivables collection periods
A24: (Trade receivable/ Credit sales)*365 | B24: (670/5,720)*365 | C24: (1,090/6,310)*365
B25: 43 days | C25: 63 days
A26: i. Trade payable collection period
A27: (Trade payable/ Credit purchase)*365 | B27: (450/3,840+510)*365 | C27: (1,130/4,240+890)*100
B28: 38 days | C28: 80 days
A29: j. Asset turnover ratio
A30: Sales/ Average asset | B30: (5,720/2,000+2,820+500) | C30: (6,310/2,000+1,030+3,500)
B31: 1.08 times | C31: 0.97 times

Sheet Q5. Theory
A1: 1 | B1: Straight Line Method
B2: Cost 8,000
B3: Yr 1 Depreciation* 1,120
B4: 6880
B5: Yr 2 Depreciation 1,120
B6: 5760
B7: Yr 3 Depreciation 1,120
B8: 4640
B9: Yr 4 Depreciation 1,120
B10: 3520
B11: Yr 4 Depreciation 1,120
B12: 2400
B13: *(8,000-2,400)/5=1,120
B14: Reducing Balance
B15: Cost 8,000
B16: Yr 1 Depreciation (20% x 8,000) 1,600
B17: 6400
B18: Yr 2 Depreciation (20% x 6400) 1,280
B19: 5120
B20: Yr 3 Depreciation (20% x 5120) 1,024
B21: 4096
B22: Yr 4 Depreciation (20% x 4,096) 819
B23: 3277
B24: Yr 5 Depreciation (20% x 3,277) 655
B25: 2622
A29: 2 | B29: When utilized effectively, companies can use derivatives to efficiently manage a variety of financial risk exposures they may encounter. Three common hedging strategies involving derivatives include handling foreign exchange risks, mitigating interest rate risk, and addressing commodity or input price risks. Some examples of derivatives are futures, forwards, options, and swaps.
B31: Futures: Futures are standardized contracts organized by exchanges that specify the size, delivery time, and price of a commodity. They are easily tradable due to their standardized nature, and different aspects are specified for each commodity traded in a futures contract.
B33: Forwards: Forwards and futures are very similar, as they both grant access to a commodity at a predetermined price and time in the future. The key distinction is that a forward is traded directly between two parties without the use of an exchange. This absence of an exchange allows for negotiable terms regarding delivery, size, and price of the contract. Unlike futures, forwards are typically executed upon maturity, as they are primarily used as insurance against adverse price movements, and actual delivery of the commodity takes place. In contrast, futures are widely employed by speculators who aim to profit by selling the contracts at a higher price, and therefore, they are closed prior to maturity.
B34: Swap: A swap is an agreement between two parties to exchange cash flows on a specified date or, in many cases, on multiple dates. Typically, one party agrees to pay a fixed rate while the other party pays a floating rate. For example, in trading commodities, an airline company that relies on kerosene might agree to pay a fixed price for a predetermined quantity of this commodity. The other party, a bank, agrees to pay the spot price for the commodity. This arrangement ensures that the airline company knows the price it will pay for its commodity. If the price of the commodity rises, the bank covers the difference, but if it falls, the difference is paid to the bank.
A36: 3 | B36: Accounting is the process of recording, summarizing, analyzing, and reporting financial transactions of a business or an organization. It helps in tracking income, expenses, assets, and liabilities to ensure financial transparency and decision-making.
B37: Accounting consists of several key activities: Recording Transactions (Bookkeeping), Classifying and Summarizing Data, Financial Analysis and Interpretation, Preparing Financial Statements (e.g., Balance Sheet, Income Statement), Auditing and Compliance
B38: Internal Users
B39: Owners/Management – They use accounting reports to make strategic decisions, such as expanding the business or cutting costs. Example: A company's CEO analyzes the profit and loss statement to decide whether to invest in new machinery. Employees – Workers and unions use financial statements to negotiate salaries, bonuses, and job security. Example: An employee union reviews the company's annual financial report to demand better wages. Managers – Departmental heads use accounting reports to track performance, budget, and control expenses. Example: A sales manager checks revenue data to evaluate if the sales targets are met.
B40: External Users
B41: Investors & Shareholders – They analyze financial statements to assess profitability and decide whether to invest. Example: A stock market investor studies a company’s earnings report before buying shares. Creditors & Lenders – Banks and financial institutions check financial health before giving loans. Example: A bank reviews a company's balance sheet before approving a loan. Government & Tax Authorities – The government uses financial reports for taxation and regulatory purposes. Example: The IRS examines a company’s income statement to ensure tax compliance. Suppliers & Vendors – They evaluate a company's financial stability before offering goods on credit. Example: A supplier reviews a retail store’s credit history before supplying goods on a 30-day credit. Customers – Large clients may check a company’s stability to ensure long-term business relationships. Example: A multinational corporation reviews its vendor’s financial strength before signing a long-term contract. Public & Media – Analysts and reporters use financial reports to assess industry trends and corporate performance. Example: A financial journalist writes an article on Apple’s annual earnings report.
A43: 4 | B43: Sources of Finance
B44: Internal sources of finance
B45: – Long term finance
B46: • Retained profits
B47: – Short-term finance
...

Sheet Q6. Cash budget
B1: July | C1: Aug | D1: Sept | E1: Oct
A3: INCOME: | C3: £ | D3: £ | E3: £
A5: Cash Sales | B5: 10000 | C5: 20000 | D5: 32500 | E5: 47500
A6: Credit Sales (1mth) | B6: - | C6: 6000 | D6: 12000 | E6: 19500
A7: Credit Sales (2mth) | B7: - | C7: - | D7: 3700 | E7: 7400
A8: Total Income (A) | B8: 10000 | C8: 26000 | D8: 48200 | E8: 74400
A9: EXPENDITURE:
A11: Cash Purchases | B11: - | C11: 40000 | D11: 45000 | E11: 55000
A12: Advertising | B12: - | C12: 5000 | D12: 5000 | E12: -
A13: Machine | B13: - | C13: - | D13: 15000 | E13: -
A14: Rental | B14: 4000 | C14: - | D14: - | E14: 4000
A15: Fixed Costs (1300-800) | B15: 800 | C15: 800 | D15: 800 | E15: 800
A16: Salaries and Wages | B16: 2500 | C16: 2500 | D16: 2500 | E16: 2500
A17: Other Expenses | B17: - | C17: 550 | D17: 550 | E17: 550
A18: Total Expenditure (B) | B18: 7300 | C18: 48850 | D18: 68850 | E18: 62850
A20: Net Income (A-B) | B20: 2700 | C20: -22850 | D20: -20650 | E20: 11550
A22: Opening Balance | B22: 30000 | C22: 32700 | D22: 9850 | E22: -10800
A23: Net Income (A-B) | B23: 2700 | C23: -22850 | D23: -20650 | E23: 11550
A24: Closing Balance | B24: 32700 | C24: 9850 | D24: -10800 | E24: 750
